<?xml version="1.0"?>
<robot name="valvePanel">

   <link name="bar">
      <visual>
	<origin rpy="0 0 1.75" xyz="0.0 0.0 0.0"/> 
	 <geometry>
	   <mesh filename="package://udg_pandora/data2/objects2/handle.osg"/> 
	 </geometry>
      </visual>
   </link>

   <link name="handle">
      <visual>
	<origin rpy="0 0 0" xyz="0.0 0 0.0"/> 
	 <geometry>
	   <mesh filename="package://udg_pandora/data2/objects2/handle.osg"/> 
	 </geometry>
      </visual>
   </link>

   <joint name="valve" type="continuous">
      <parent link="bar"/>
      <child link="handle"/>
      <axis xyz="1 0 0"/>   
      <origin rpy="0 0 0" xyz="0.05 0.01 0.0"/>
   </joint>


</robot>
